Workbook

Sheet Panduan
B2: Mining ESG Award — Panduan Penilaian
B3: Kerangka penilaian tersegmentasi untuk peserta IUP dan IUJP (per sub-jenis layanan)
B6: 1. Struktur Workbook
B7: • Profil Peserta : isi identitas peserta dan pilih Jenis Izin (IUP/IUJP) + Sub-Jenis Layanan (khusus IUJP). Pilihan ini mengendalikan seluruh sheet lain secara otomatis.
B8: • Bobot Kategori : tabel bobot target Environmental/Social/Governance untuk setiap profil peserta.
B9: • Maturity : definisi level kematangan 0-5 (tidak berubah dari versi sebelumnya).
B10: • Master Checklist : seluruh kriteria penilaian (gabungan IUP + semua sub-jenis IUJP) dengan kolom Applicability. Kriteria yang tidak relevan dengan profil peserta terpilih otomatis di-nonaktifkan (bobot = 0) dan bobot kriteria yang relevan dinormalisasi ulang agar total tetap 100% per kategori.
B11: • ESG Score Summary: rekap skor per pilar (E/S/G) hasil normalisasi.
B12: • Award Level : penentuan level kematangan & kategori Award berdasarkan skor 0-5 per pilar.
B13: • Red Flag : aturan veto/diskualifikasi — berlaku sama untuk IUP maupun IUJP.
B15: 2. Cara Pakai
B16: 1) Buka sheet 'Profil Peserta', isi nama perusahaan dan pilih Jenis Izin.
... B30: • IUJP - Jasa Penunjang : camp & catering, logistik non-alat berat, keamanan, jasa penunjang lain.

Sheet Profil Peserta
B2: Profil Peserta ESG Award
B4: Nama Perusahaan
B5: Nomor Izin (IUP/IUJP)
B6: Tanggal Assessment
B7: Nama Assessor (CBQA)
B8: Jenis Izin | C8: IUP
B9: Sub-Jenis Layanan Utama (khusus IUJP) | C9: Operasional Alat Berat & Hauling | E9: Diisi HANYA jika Jenis Izin = IUJP. Pilih sub-jenis yang paling menggambarkan lingkup usaha utama peserta. Lihat sheet 'Panduan' bagian 4 untuk definisi masing-masing.
B11: Kode Profil (otomatis) | C11: =IF(C8="IUP","IUP",IF(C9="Konsultasi & Perencanaan","IUJP-KONSULTASI",IF(C9="Operasional Alat Berat & Hauling","IUJP-OPERASIONAL",IF(C9="Pengeboran & Peledakan","IUJP-DRILLING",IF(C9="Pengolahan & Pemurnian","IUJP-PENGOLAHAN",IF(C9="Jasa Penunjang","IUJP-PENUNJANG","BELUM DIPILIH")))))) -> IUP | E11: Sel ini dipakai formula di sheet lain (Master Checklist, ESG Score Summary, Award Level). Jangan dihapus atau dipindah.

Sheet Bobot Kategori
B2: Bobot Target per Pilar (E / S / G)
B3: Total bobot tiap profil = 100%. Digunakan sebagai target normalisasi di Master Checklist.
B5: Kode Profil | C5: Environmental | D5: Social | E5: Governance | F5: Rasional Singkat | G5: Total
B6: IUP | C6: 0.35 | D6: 0.4 | E6: 0.25 | F6: Pemegang izin tambang; kendali penuh atas jejak lingkungan tapak (tailing, biodiversitas, closure). | G6: =C6+D6+E6 -> 1
B7: IUJP-KONSULTASI | C7: 0.1 | D7: 0.5 | E7: 0.4 | F7: Jasa berbasis kantor/lab; jejak lingkungan operasional minim, governance & kualitas data jadi kunci. | G7: =C7+D7+E7 -> 1
B8: IUJP-OPERASIONAL | C8: 0.25 | D8: 0.45 | E8: 0.3 | F8: Alat berat & hauling; jejak emisi/BBM signifikan, risiko K3 tinggi. | G8: =C8+D8+E8 -> 1
B9: IUJP-DRILLING | C9: 0.25 | D9: 0.45 | E9: 0.3 | F9: Pengeboran & peledakan; risiko K3 & lingkungan spesifik (lumpur bor, getaran, kebisingan). | G9: =C9+D9+E9 -> 1
B10: IUJP-PENGOLAHAN | C10: 0.3 | D10: 0.4 | E10: 0.3 | F10: Kontraktor pengolahan/pemurnian; jejak air & limbah proses mendekati profil IUP. | G10: =C10+D10+E10 -> 1
B11: IUJP-PENUNJANG | C11: 0.1 | D11: 0.55 | E11: 0.35 | F11: Camp, catering, logistik non-alat berat; dominan isu kesejahteraan pekerja & governance kontraktual. | G11: =C11+D11+E11 -> 1

Sheet Maturity
B2: Skala Maturity Level (0-5)
B4: Skor | C4: Level | D4: Deskripsi
B5: 0 | C5: Tidak Ada | D5: Tidak ada kebijakan, praktik, atau bukti sama sekali terkait kriteria ini.
B6: 1 | C6: Ad-hoc | D6: Praktik dilakukan secara tidak konsisten/reaktif, tanpa dokumentasi formal.
B7: 2 | C7: Foundational | D7: Kebijakan/prosedur tertulis sudah ada, implementasi masih terbatas atau baru dimulai.
B8: 3 | C8: Integration | D8: Diterapkan secara konsisten di seluruh unit terkait, dengan monitoring rutin.
B9: 4 | C9: Advanced | D9: Terintegrasi dalam sistem manajemen, ada target terukur dan evaluasi berkala.
B10: 5 | C10: Leadership | D10: Praktik terbaik industri, terverifikasi independen, menjadi acuan/benchmark sektor.
B13: Level Kematangan Kategori (rata-rata skor 0-5 dalam satu pilar E/S/G):
B14: 0.0 - < 2.0 | C14: Belum Memenuhi (Not Yet Qualified)
B15: 2.0 - < 3.0 | C15: Foundation
B16: 3.0 - < 4.0 | C16: Integration
B17: 4.0 - 5.0 | C17: Leadership

Sheet Master Checklist
B2: Master Checklist — ESG Award (IUP & IUJP)
B3: ="Profil Peserta Aktif: " & 'Profil Peserta'!$C$11 -> Profil Peserta Aktif: IUP
B6: No | C6: Kategori | D6: Sub-Kategori | E6: Kode | F6: Kriteria Pertanyaan | G6: Bukti / Evidence | H6: Applicability Tag | I6: Bobot Dasar | J6: Skor Asesor (0-5) | K6: Berlaku? | L6: Bobot Ternormalisasi | M6: Skor Terbobot
B7: 1 | C7: Environmental | D7: Tailing & Air | E7: 1.1 | F7: Desain dan tinjauan independen (Engineer of Record) fasilitas tailing | G7: Laporan EoR, sertifikat desain | H7: IUP | I7: 0.02 | J7: 5 | K7: =IF(ISNUMBER(SEARCH(","&'Profil Peserta'!$C$11&",", ","&H7&",")),1,0) -> 1 | L7: =IF(K7=0,0,(I7/SUMIFS($I$7:$I$55,$C$7:$C$55,C7,$K$7:$K$55,1))*INDEX('Bobot Kategori'!$C$6:$E$11,MATCH('Profil Peserta'!$C$11,'Bobot Kategori'!$B$6:$B$11,0),MATCH(C7,'Bobot Kategori'!$C$5:$E$5,0))) -> 0.0175 | M7: =L7*J7 -> 0.0875
B8: 2 | C8: Environmental | D8: Tailing & Air | E8: 1.2 | F8: Instrumentasi dan pemantauan stabilitas tailing berjalan | G8: Data monitoring piezometer/inklinometer | H8: IUP | I8: 0.03 | J8: 5 | K8: =IF(ISNUMBER(SEARCH(","&'Profil Peserta'!$C$11&",", ","&H8&",")),1,0) -> 1 | L8: =IF(K8=0,0,(I8/SUMIFS($I$7:$I$55,$C$7:$C$55,C8,$K$7:$K$55,1))*INDEX('Bobot Kategori'!$C$6:$E$11,MATCH('Profil Peserta'!$C$11,'Bobot Kategori'!$B$6:$B$11,0),MATCH(C8,'Bobot Kategori'!$C$5:$E$5,0))) -> 0.02625 | M8: =L8*J8 -> 0.13125
B9: 3 | C9: Environmental | D9: Tailing & Air | E9: 1.3 | F9: Rencana tanggap darurat (ERP) tailing dan simulasi berkala | G9: Dokumen ERP, berita acara simulasi | H9: IUP | I9: 0.03 | J9: 5 | K9: =IF(ISNUMBER(SEARCH(","&'Profil Peserta'!$C$11&",", ","&H9&",")),1,0) -> 1 | L9: =IF(K9=0,0,(I9/SUMIFS($I$7:$I$55,$C$7:$C$55,C9,$K$7:$K$55,1))*INDEX('Bobot Kategori'!$C$6:$E$11,MATCH('Profil Peserta'!$C$11,'Bobot Kategori'!$B$6:$B$11,0),MATCH(C9,'Bobot Kategori'!$C$5:$E$5,0))) -> 0.02625 | M9: =L9*J9 -> 0.13125
B10: 4 | C10: Environmental | D10: Tailing & Air | E10: 1.4 | F10: Neraca air (water balance) tapak operasi terverifikasi | G10: Laporan neraca air tahunan | H10: IUP,IUJP-PENGOLAHAN | I10: 0.03 | J10: 5 | K10: =IF(ISNUMBER(SEARCH(","&'Profil Peserta'!$C$11&",", ","&H10&",")),1,0) -> 1 | L10: =IF(K10=0,0,(I10/SUMIFS($I$7:$I$55,$C$7:$C$55,C10,$K$7:$K$55,1))*INDEX('Bobot Kategori'!$C$6:$E$11,MATCH('Profil Peserta'!$C$11,'Bobot Kategori'!$B$6:$B$11,0),MATCH(C10,'Bobot Kategori'!$C$5:$E$5,0))) -> 0.02625 | M10: =L10*J10 -> 0.13125
B11: 5 | C11: Environmental | D11: Tailing & Air | E11: 1.5 | F11: Tingkat daur ulang air (water recycle rate) | G11: Data volume air daur ulang vs total pemakaian | H11: IUP,IUJP-PENGOLAHAN | I11: 0.02 | J11: 5 | K11: =IF(ISNUMBER(SEARCH(","&'Profil Peserta'!$C$11&",", ","&H11&",")),1,0) -> 1 | L11: =IF(K11=0,0,(I11/SUMIFS($I$7:$I$55,$C$7:$C$55,C11,$K$7:$K$55,1))*INDEX('Bobot Kategori'!$C$6:$E$11,MATCH('Profil Peserta'!$C$11,'Bobot Kategori'!$B$6:$B$11,0),MATCH(C11,'Bobot Kategori'!$C$5:$E$5,0))) -> 0.0175 | M11: =L11*J11 -> 0.0875
B12: 6 | C12: Environmental | D12: Tailing & Air | E12: 1.6 | F12: Kualitas efluen memenuhi baku mutu | G12: Hasil uji lab efluen berkala | H12: IUP,IUJP-PENGOLAHAN | I12: 0.02 | J12: 5 | K12: =IF(ISNUMBER(SEARCH(","&'Profil Peserta'!$C$11&",", ","&H12&",")),1,0) -> 1 | L12: =IF(K12=0,0,(I12/SUMIFS($I$7:$I$55,$C$7:$C$55,C12,$K$7:$K$55,1))*INDEX('Bobot Kategori'!$C$6:$E$11,MATCH('Profil Peserta'!$C$11,'Bobot Kategori'!$B$6:$B$11,0),MATCH(C12,'Bobot Kategori'!$C$5:$E$5,0))) -> 0.0175 | M12: =L12*J12 -> 0.0875
B13: 7 | C13: Environmental | D13: Biodiversitas & Closure | E13: 2.1 | F13: Studi baseline keanekaragaman hayati sebelum gangguan lahan | G13: Laporan baseline biodiversitas | H13: IUP | I13: 0.02 | J13: 5 | K13: =IF(ISNUMBER(SEARCH(","&'Profil Peserta'!$C$11&",", ","&H13&",")),1,0) -> 1 | L13: =IF(K13=0,0,(I13/SUMIFS($I$7:$I$55,$C$7:$C$55,C13,$K$7:$K$55,1))*INDEX('Bobot Kategori'!$C$6:$E$11,MATCH('Profil Peserta'!$C$11,'Bobot Kategori'!$B$6:$B$11,0),MATCH(C13,'Bobot Kategori'!$C$5:$E$5,0))) -> 0.0175 | M13: =L13*J13 -> 0.0875
B14: 8 | C14: Environmental | D14: Biodiversitas & Closure | E14: 2.2 | F14: Adopsi kerangka pengungkapan TNFD atau setara | G14: Laporan TNFD/nature-related disclosure | H14: IUP | I14: 0.02 | J14: 5 | K14: =IF(ISNUMBER(SEARCH(","&'Profil Peserta'!$C$11&",", ","&H14&",")),1,0) -> 1 | L14: =IF(K14=0,0,(I14/SUMIFS($I$7:$I$55,$C$7:$C$55,C14,$K$7:$K$55,1))*INDEX('Bobot Kategori'!$C$6:$E$11,MATCH('Profil Peserta'!$C$11,'Bobot Kategori'!$B$6:$B$11,0),MATCH(C14,'Bobot Kategori'!$C$5:$E$5,0))) -> 0.0175 | M14: =L14*J14 -> 0.0875
B15: 9 | C15: Environmental | D15: Biodiversitas & Closure | E15: 2.3 | F15: Sertifikasi ISO 14001 (Sistem Manajemen Lingkungan) aktif | G15: Sertifikat ISO 14001 dan lingkup sertifikasi | H15: IUP,IUJP-KONSULTASI,IUJP-OPERASIONAL,IUJP-DRILLING,IUJP-PENGOLAHAN,IUJP-PENUNJANG | I15: 0.03 | J15: 5 | K15: =IF(ISNUMBER(SEARCH(","&'Profil Peserta'!$C$11&",", ","&H15&",")),1,0) -> 1 | L15: =IF(K15=0,0,(I15/SUMIFS($I$7:$I$55,$C$7:$C$55,C15,$K$7:$K$55,1))*INDEX('Bobot Kategori'!$C$6:$E$11,MATCH('Profil Peserta'!$C$11,'Bobot Kategori'!$B$6:$B$11,0),MATCH(C15,'Bobot Kategori'!$C$5:$E$5,0))) -> 0.02625 | M15: =L15*J15 -> 0.13125
B16: 10 | C16: Environmental | D16: Biodiversitas & Closure | E16: 2.4 | F16: Dana jaminan reklamasi/closure tersedia (escrow) | G16: Bukti penempatan dana jaminan | H16: IUP | I16: 0.02 | J16: 5 | K16: =IF(ISNUMBER(SEARCH(","&'Profil Peserta'!$C$11&",", ","&H16&",")),1,0) -> 1 | L16: =IF(K16=0,0,(I16/SUMIFS($I$7:$I$55,$C$7:$C$55,C16,$K$7:$K$55,1))*INDEX('Bobot Kategori'!$C$6:$E$11,MATCH('Profil Peserta'!$C$11,'Bobot Kategori'!$B$6:$B$11,0),MATCH(C16,'Bobot Kategori'!$C$5:$E$5,0))) -> 0.0175 | M16: =L16*J16 -> 0.0875
B17: 11 | C17: Environmental | D17: Biodiversitas & Closure | E17: 2.5 | F17: Realisasi reklamasi progresif sesuai rencana | G17: Laporan realisasi reklamasi vs RKAB | H17: IUP | I17: 0.02 | J17: 5 | K17: =IF(ISNUMBER(SEARCH(","&'Profil Peserta'!$C$11&",", ","&H17&",")),1,0) -> 1 | L17: =IF(K17=0,0,(I17/SUMIFS($I$7:$I$55,$C$7:$C$55,C17,$K$7:$K$55,1))*INDEX('Bobot Kategori'!$C$6:$E$11,MATCH('Profil Peserta'!$C$11,'Bobot Kategori'!$B$6:$B$11,0),MATCH(C17,'Bobot Kategori'!$C$5:$E$5,0))) -> 0.0175 | M17: =L17*J17 -> 0.0875
B18: 12 | C18: Environmental | D18: Dekarbonisasi | E18: 3.1 | F18: Inventarisasi GRK Scope 1 & 2 mengacu ISO 14064-1 | G18: Laporan inventarisasi GRK terverifikasi | H18: IUP,IUJP-KONSULTASI,IUJP-OPERASIONAL,IUJP-DRILLING,IUJP-PENGOLAHAN,IUJP-PENUNJANG | I18: 0.03 | J18: 5 | K18: =IF(ISNUMBER(SEARCH(","&'Profil Peserta'!$C$11&",", ","&H18&",")),1,0) -> 1 | L18: =IF(K18=0,0,(I18/SUMIFS($I$7:$I$55,$C$7:$C$55,C18,$K$7:$K$55,1))*INDEX('Bobot Kategori'!$C$6:$E$11,MATCH('Profil Peserta'!$C$11,'Bobot Kategori'!$B$6:$B$11,0),MATCH(C18,'Bobot Kategori'!$C$5:$E$5,0))) -> 0.02625 | M18: =L18*J18 -> 0.13125
... B23: 17 | C23: Environmental | D23: Jejak Operasional Jasa (IUJP) | E23: 3.6 | F23: Program manajemen tumpahan B3/BBM di area kerja | G23: SOP spill management, catatan insiden tumpahan | H23: IUP,IUJP-OPERASIONAL,IUJP-DRILLING,IUJP-PENGOLAHAN | I23: 0.02 | J23: 5 | K23: =IF(ISNUMBER(SEARCH(","&'Profil Peserta'!$C$11&",", ","&H23&",")),1,0) -> 1 | L23: =IF(K23=0,0,(I23/SUMIFS($I$7:$I$55,$C$7:$C$55,C23,$K$7:$K$55,1))*INDEX('Bobot Kategori'!$C$6:$E$11,MATCH('Profil Peserta'!$C$11,'Bobot Kategori'!$B$6:$B$11,0),MATCH(C23,'Bobot Kategori'!$C$5:$E$5,0))) -> 0.0175 | M23: =L23*J23 -> 0.0875
B24: 18 | C24: Environmental | D24: Jejak Operasional Jasa (IUJP) | E24: 3.7 | F24: Pemantauan dan pengendalian debu/emisi dari aktivitas hauling & alat berat | G24: Data pemantauan kualitas udara, jadwal penyiraman jalan | H24: IUJP-OPERASIONAL | I24: 0.02 | K24: =IF(ISNUMBER(SEARCH(","&'Profil Peserta'!$C$11&",", ","&H24&",")),1,0) -> 0 | L24: =IF(K24=0,0,(I24/SUMIFS($I$7:$I$55,$C$7:$C$55,C24,$K$7:$K$55,1))*INDEX('Bobot Kategori'!$C$6:$E$11,MATCH('Profil Peserta'!$C$11,'Bobot Kategori'!$B$6:$B$11,0),MATCH(C24,'Bobot Kategori'!$C$5:$E$5,0))) -> 0 | M24: =L24*J24 -> 0
B25: 19 | C25: Environmental | D25: Jejak Operasional Jasa (IUJP) | E25: 3.8 | F25: Pengelolaan lumpur pemboran (drilling mud) & cutting sesuai baku mutu limbah B3 | G25: Manifest limbah B3, SOP pengelolaan mud & cutting | H25: IUJP-DRILLING | I25: 0.02 | K25: =IF(ISNUMBER(SEARCH(","&'Profil Peserta'!$C$11&",", ","&H25&",")),1,0) -> 0 | L25: =IF(K25=0,0,(I25/SUMIFS($I$7:$I$55,$C$7:$C$55,C25,$K$7:$K$55,1))*INDEX('Bobot Kategori'!$C$6:$E$11,MATCH('Profil Peserta'!$C$11,'Bobot Kategori'!$B$6:$B$11,0),MATCH(C25,'Bobot Kategori'!$C$5:$E$5,0))) -> 0 | M25: =L25*J25 -> 0
B26: 20 | C26: Environmental | D26: Jejak Operasional Jasa (IUJP) | E26: 3.9 | F26: Manajemen getaran (blast vibration) dan kebisingan aktivitas peledakan | G26: Data monitoring vibrasi/kebisingan, izin peledakan | H26: IUJP-DRILLING | I26: 0.02 | K26: =IF(ISNUMBER(SEARCH(","&'Profil Peserta'!$C$11&",", ","&H26&",")),1,0) -> 0 | L26: =IF(K26=0,0,(I26/SUMIFS($I$7:$I$55,$C$7:$C$55,C26,$K$7:$K$55,1))*INDEX('Bobot Kategori'!$C$6:$E$11,MATCH('Profil Peserta'!$C$11,'Bobot Kategori'!$B$6:$B$11,0),MATCH(C26,'Bobot Kategori'!$C$5:$E$5,0))) -> 0 | M26: =L26*J26 -> 0
B27: 21 | C27: Environmental | D27: Jejak Operasional Jasa (IUJP) | E27: 3.10 | F27: Pengelolaan limbah proses pengolahan/pemurnian sesuai baku mutu B3 | G27: Manifest limbah proses, hasil uji lab | H27: IUJP-PENGOLAHAN | I27: 0.02 | K27: =IF(ISNUMBER(SEARCH(","&'Profil Peserta'!$C$11&",", ","&H27&",")),1,0) -> 0 | L27: =IF(K27=0,0,(I27/SUMIFS($I$7:$I$55,$C$7:$C$55,C27,$K$7:$K$55,1))*INDEX('Bobot Kategori'!$C$6:$E$11,MATCH('Profil Peserta'!$C$11,'Bobot Kategori'!$B$6:$B$11,0),MATCH(C27,'Bobot Kategori'!$C$5:$E$5,0))) -> 0 | M27: =L27*J27 -> 0
B28: 22 | C28: Environmental | D28: Jejak Operasional Jasa (IUJP) | E28: 3.11 | F28: Praktik manajemen lingkungan kantor/basecamp (sampah, efisiensi energi, digitalisasi dokumen) | G28: Kebijakan green office, data pemilahan sampah | H28: IUJP-KONSULTASI,IUJP-PENUNJANG | I28: 0.03 | K28: =IF(ISNUMBER(SEARCH(","&'Profil Peserta'!$C$11&",", ","&H28&",")),1,0) -> 0 | L28: =IF(K28=0,0,(I28/SUMIFS($I$7:$I$55,$C$7:$C$55,C28,$K$7:$K$55,1))*INDEX('Bobot Kategori'!$C$6:$E$11,MATCH('Profil Peserta'!$C$11,'Bobot Kategori'!$B$6:$B$11,0),MATCH(C28,'Bobot Kategori'!$C$5:$E$5,0))) -> 0 | M28: =L28*J28 -> 0
B29: 23 | C29: Environmental | D29: Jejak Operasional Jasa (IUJP) | E29: 3.12 | F29: Pengelolaan limbah domestik & sanitasi camp/mess pekerja | G29: SOP pengelolaan limbah domestik, hasil inspeksi sanitasi | H29: IUJP-PENUNJANG | I29: 0.02 | K29: =IF(ISNUMBER(SEARCH(","&'Profil Peserta'!$C$11&",", ","&H29&",")),1,0) -> 0 | L29: =IF(K29=0,0,(I29/SUMIFS($I$7:$I$55,$C$7:$C$55,C29,$K$7:$K$55,1))*INDEX('Bobot Kategori'!$C$6:$E$11,MATCH('Profil Peserta'!$C$11,'Bobot Kategori'!$B$6:$B$11,0),MATCH(C29,'Bobot Kategori'!$C$5:$E$5,0))) -> 0 | M29: =L29*J29 -> 0
B30: 24 | C30: Social | D30: Keselamatan & Kesehatan Kerja | E30: 4.1 | F30: Sertifikasi ISO 45001 (SMK3) aktif | G30: Sertifikat ISO 45001 | H30: IUP,IUJP-KONSULTASI,IUJP-OPERASIONAL,IUJP-DRILLING,IUJP-PENGOLAHAN,IUJP-PENUNJANG | I30: 0.05 | J30: 5 | K30: =IF(ISNUMBER(SEARCH(","&'Profil Peserta'!$C$11&",", ","&H30&",")),1,0) -> 1 | L30: =IF(K30=0,0,(I30/SUMIFS($I$7:$I$55,$C$7:$C$55,C30,$K$7:$K$55,1))*INDEX('Bobot Kategori'!$C$6:$E$11,MATCH('Profil Peserta'!$C$11,'Bobot Kategori'!$B$6:$B$11,0),MATCH(C30,'Bobot Kategori'!$C$5:$E$5,0))) -> 0.048780488 | M30: =L30*J30 -> 0.24390244
B31: 25 | C31: Social | D31: Keselamatan & Kesehatan Kerja | E31: 4.2 | F31: Lost Time Injury / Total Recordable Injury Frequency Rate (LTIFR/TRIFR) | G31: Data statistik kecelakaan kerja 3 tahun terakhir | H31: IUP,IUJP-KONSULTASI,IUJP-OPERASIONAL,IUJP-DRILLING,IUJP-PENGOLAHAN,IUJP-PENUNJANG | I31: 0.04 | J31: 5 | K31: =IF(ISNUMBER(SEARCH(","&'Profil Peserta'!$C$11&",", ","&H31&",")),1,0) -> 1 | L31: =IF(K31=0,0,(I31/SUMIFS($I$7:$I$55,$C$7:$C$55,C31,$K$7:$K$55,1))*INDEX('Bobot Kategori'!$C$6:$E$11,MATCH('Profil Peserta'!$C$11,'Bobot Kategori'!$B$6:$B$11,0),MATCH(C31,'Bobot Kategori'!$C$5:$E$5,0))) -> 0.03902439 | M31: =L31*J31 -> 0.19512195
B32: 26 | C32: Social | D32: Keselamatan & Kesehatan Kerja | E32: 4.3 | F32: Catatan fatalitas kerja dan investigasi akar masalah | G32: Laporan investigasi insiden fatal (jika ada) | H32: IUP,IUJP-KONSULTASI,IUJP-OPERASIONAL,IUJP-DRILLING,IUJP-PENGOLAHAN,IUJP-PENUNJANG | I32: 0.04 | J32: 5 | K32: =IF(ISNUMBER(SEARCH(","&'Profil Peserta'!$C$11&",", ","&H32&",")),1,0) -> 1 | L32: =IF(K32=0,0,(I32/SUMIFS($I$7:$I$55,$C$7:$C$55,C32,$K$7:$K$55,1))*INDEX('Bobot Kategori'!$C$6:$E$11,MATCH('Profil Peserta'!$C$11,'Bobot Kategori'!$B$6:$B$11,0),MATCH(C32,'Bobot Kategori'!$C$5:$E$5,0))) -> 0.03902439 | M32: =L32*J32 -> 0.19512195
B33: 27 | C33: Social | D33: Keselamatan & Kesehatan Kerja | E33: 4.4 | F33: Program kesehatan kerja & kesehatan mental pekerja | G33: Dokumen program, data partisipasi | H33: IUP,IUJP-KONSULTASI,IUJP-OPERASIONAL,IUJP-DRILLING,IUJP-PENGOLAHAN,IUJP-PENUNJANG | I33: 0.03 | J33: 5 | K33: =IF(ISNUMBER(SEARCH(","&'Profil Peserta'!$C$11&",", ","&H33&",")),1,0) -> 1 | L33: =IF(K33=0,0,(I33/SUMIFS($I$7:$I$55,$C$7:$C$55,C33,$K$7:$K$55,1))*INDEX('Bobot Kategori'!$C$6:$E$11,MATCH('Profil Peserta'!$C$11,'Bobot Kategori'!$B$6:$B$11,0),MATCH(C33,'Bobot Kategori'!$C$5:$E$5,0))) -> 0.029268293 | M33: =L33*J33 -> 0.14634146
B34: 28 | C34: Social | D34: Keselamatan & Kesehatan Kerja | E34: 4.5 | F34: Penerapan Stop Work Authority (hak berhenti kerja jika tidak aman) | G34: Kebijakan SWA, contoh penerapan/insiden | H34: IUP,IUJP-KONSULTASI,IUJP-OPERASIONAL,IUJP-DRILLING,IUJP-PENGOLAHAN,IUJP-PENUNJANG | I34: 0.03 | J34: 5 | K34: =IF(ISNUMBER(SEARCH(","&'Profil Peserta'!$C$11&",", ","&H34&",")),1,0) -> 1 | L34: =IF(K34=0,0,(I34/SUMIFS($I$7:$I$55,$C$7:$C$55,C34,$K$7:$K$55,1))*INDEX('Bobot Kategori'!$C$6:$E$11,MATCH('Profil Peserta'!$C$11,'Bobot Kategori'!$B$6:$B$11,0),MATCH(C34,'Bobot Kategori'!$C$5:$E$5,0))) -> 0.029268293 | M34: =L34*J34 -> 0.14634146
B35: 29 | C35: Social | D35: Masyarakat & Lahan | E35: 5.1 | F35: Proses FPIC (Free, Prior, Informed Consent) untuk akuisisi lahan baru | G35: Dokumentasi konsultasi & persetujuan masyarakat | H35: IUP | I35: 0.03 | J35: 5 | K35: =IF(ISNUMBER(SEARCH(","&'Profil Peserta'!$C$11&",", ","&H35&",")),1,0) -> 1 | L35: =IF(K35=0,0,(I35/SUMIFS($I$7:$I$55,$C$7:$C$55,C35,$K$7:$K$55,1))*INDEX('Bobot Kategori'!$C$6:$E$11,MATCH('Profil Peserta'!$C$11,'Bobot Kategori'!$B$6:$B$11,0),MATCH(C35,'Bobot Kategori'!$C$5:$E$5,0))) -> 0.029268293 | M35: =L35*J35 -> 0.14634146
B36: 30 | C36: Social | D36: Masyarakat & Lahan | E36: 5.2 | F36: Mekanisme keluhan (grievance) yang dapat diakses masyarakat/pekerja | G36: SOP grievance, log keluhan | H36: IUP,IUJP-KONSULTASI,IUJP-OPERASIONAL,IUJP-DRILLING,IUJP-PENGOLAHAN,IUJP-PENUNJANG | I36: 0.03 | J36: 5 | K36: =IF(ISNUMBER(SEARCH(","&'Profil Peserta'!$C$11&",", ","&H36&",")),1,0) -> 1 | L36: =IF(K36=0,0,(I36/SUMIFS($I$7:$I$55,$C$7:$C$55,C36,$K$7:$K$55,1))*INDEX('Bobot Kategori'!$C$6:$E$11,MATCH('Profil Peserta'!$C$11,'Bobot Kategori'!$B$6:$B$11,0),MATCH(C36,'Bobot Kategori'!$C$5:$E$5,0))) -> 0.029268293 | M36: =L36*J36 -> 0.14634146
B37: 31 | C37: Social | D37: Masyarakat & Lahan | E37: 5.3 | F37: Persentase keluhan yang terselesaikan tepat waktu | G37: Data tracking penyelesaian keluhan | H37: IUP,IUJP-KONSULTASI,IUJP-OPERASIONAL,IUJP-DRILLING,IUJP-PENGOLAHAN,IUJP-PENUNJANG | I37: 0.02 | J37: 5 | K37: =IF(ISNUMBER(SEARCH(","&'Profil Peserta'!$C$11&",", ","&H37&",")),1,0) -> 1 | L37: =IF(K37=0,0,(I37/SUMIFS($I$7:$I$55,$C$7:$C$55,C37,$K$7:$K$55,1))*INDEX('Bobot Kategori'!$C$6:$E$11,MATCH('Profil Peserta'!$C$11,'Bobot Kategori'!$B$6:$B$11,0),MATCH(C37,'Bobot Kategori'!$C$5:$E$5,0))) -> 0.019512195 | M37: =L37*J37 -> 0.097560976
B38: 32 | C38: Social | D38: Masyarakat & Lahan | E38: 5.4 | F38: Program pengembangan ekonomi masyarakat (Community Development) | G38: Laporan realisasi program CD/CSR | H38: IUP | I38: 0.03 | J38: 5 | K38: =IF(ISNUMBER(SEARCH(","&'Profil Peserta'!$C$11&",", ","&H38&",")),1,0) -> 1 | L38: =IF(K38=0,0,(I38/SUMIFS($I$7:$I$55,$C$7:$C$55,C38,$K$7:$K$55,1))*INDEX('Bobot Kategori'!$C$6:$E$11,MATCH('Profil Peserta'!$C$11,'Bobot Kategori'!$B$6:$B$11,0),MATCH(C38,'Bobot Kategori'!$C$5:$E$5,0))) -> 0.029268293 | M38: =L38*J38 -> 0.14634146
B39: 33 | C39: Social | D39: Masyarakat & Lahan | E39: 5.5 | F39: Pemantauan lingkungan partisipatif bersama masyarakat | G39: Berita acara pemantauan bersama | H39: IUP | I39: 0.02 | J39: 5 | K39: =IF(ISNUMBER(SEARCH(","&'Profil Peserta'!$C$11&",", ","&H39&",")),1,0) -> 1 | L39: =IF(K39=0,0,(I39/SUMIFS($I$7:$I$55,$C$7:$C$55,C39,$K$7:$K$55,1))*INDEX('Bobot Kategori'!$C$6:$E$11,MATCH('Profil Peserta'!$C$11,'Bobot Kategori'!$B$6:$B$11,0),MATCH(C39,'Bobot Kategori'!$C$5:$E$5,0))) -> 0.019512195 | M39: =L39*J39 -> 0.097560976
B40: 34 | C40: Social | D40: Rantai Pasok & HAM | E40: 6.1 | F40: Supplier/Sub-kontraktor Code of Conduct diterapkan | G40: Dokumen code of conduct & bukti sosialisasi | H40: IUP,IUJP-KONSULTASI,IUJP-OPERASIONAL,IUJP-DRILLING,IUJP-PENGOLAHAN,IUJP-PENUNJANG | I40: 0.02 | J40: 5 | K40: =IF(ISNUMBER(SEARCH(","&'Profil Peserta'!$C$11&",", ","&H40&",")),1,0) -> 1 | L40: =IF(K40=0,0,(I40/SUMIFS($I$7:$I$55,$C$7:$C$55,C40,$K$7:$K$55,1))*INDEX('Bobot Kategori'!$C$6:$E$11,MATCH('Profil Peserta'!$C$11,'Bobot Kategori'!$B$6:$B$11,0),MATCH(C40,'Bobot Kategori'!$C$5:$E$5,0))) -> 0.019512195 | M40: =L40*J40 -> 0.097560976
B41: 35 | C41: Social | D41: Rantai Pasok & HAM | E41: 6.2 | F41: Audit K3/HAM terhadap kontraktor tier-1 | G41: Laporan audit kontraktor | H41: IUP,IUJP-KONSULTASI,IUJP-OPERASIONAL,IUJP-DRILLING,IUJP-PENGOLAHAN,IUJP-PENUNJANG | I41: 0.03 | J41: 5 | K41: =IF(ISNUMBER(SEARCH(","&'Profil Peserta'!$C$11&",", ","&H41&",")),1,0) -> 1 | L41: =IF(K41=0,0,(I41/SUMIFS($I$7:$I$55,$C$7:$C$55,C41,$K$7:$K$55,1))*INDEX('Bobot Kategori'!$C$6:$E$11,MATCH('Profil Peserta'!$C$11,'Bobot Kategori'!$B$6:$B$11,0),MATCH(C41,'Bobot Kategori'!$C$5:$E$5,0))) -> 0.029268293 | M41: =L41*J41 -> 0.14634146
... B43: 37 | C43: Social | D43: Rantai Pasok & HAM | E43: 6.4 | F43: Kebijakan anti pekerja anak & kerja paksa | G43: Dokumen kebijakan, hasil due diligence tenaga kerja | H43: IUP,IUJP-KONSULTASI,IUJP-OPERASIONAL,IUJP-DRILLING,IUJP-PENGOLAHAN,IUJP-PENUNJANG | I43: 0.02 | J43: 5 | K43: =IF(ISNUMBER(SEARCH(","&'Profil Peserta'!$C$11&",", ","&H43&",")),1,0) -> 1 | L43: =IF(K43=0,0,(I43/SUMIFS($I$7:$I$55,$C$7:$C$55,C43,$K$7:$K$55,1))*INDEX('Bobot Kategori'!$C$6:$E$11,MATCH('Profil Peserta'!$C$11,'Bobot Kategori'!$B$6:$B$11,0),MATCH(C43,'Bobot Kategori'!$C$5:$E$5,0))) -> 0.019512195 | M43: =L43*J43 -> 0.097560976
B44: 38 | C44: Social | D44: Rantai Pasok & HAM | E44: 6.5 | F44: Standar kesejahteraan pekerja lapangan (akomodasi, gizi, jam kerja & istirahat sesuai UU Ketenagakerjaan) | G44: Inspeksi camp/mess, data jam kerja & lembur | H44: IUJP-PENUNJANG,IUJP-OPERASIONAL,IUJP-DRILLING | I44: 0.03 | K44: =IF(ISNUMBER(SEARCH(","&'Profil Peserta'!$C$11&",", ","&H44&",")),1,0) -> 0 | L44: =IF(K44=0,0,(I44/SUMIFS($I$7:$I$55,$C$7:$C$55,C44,$K$7:$K$55,1))*INDEX('Bobot Kategori'!$C$6:$E$11,MATCH('Profil Peserta'!$C$11,'Bobot Kategori'!$B$6:$B$11,0),MATCH(C44,'Bobot Kategori'!$C$5:$E$5,0))) -> 0 | M44: =L44*J44 -> 0
B45: 39 | C45: Governance | D45: Integritas & Kepatuhan | E45: 7.1 | F45: Sertifikasi ISO 37001 (Sistem Manajemen Anti Penyuapan) | G45: Sertifikat ISO 37001 | H45: IUP,IUJP-KONSULTASI,IUJP-OPERASIONAL,IUJP-DRILLING,IUJP-PENGOLAHAN,IUJP-PENUNJANG | I45: 0.03 | J45: 5 | K45: =IF(ISNUMBER(SEARCH(","&'Profil Peserta'!$C$11&",", ","&H45&",")),1,0) -> 1 | L45: =IF(K45=0,0,(I45/SUMIFS($I$7:$I$55,$C$7:$C$55,C45,$K$7:$K$55,1))*INDEX('Bobot Kategori'!$C$6:$E$11,MATCH('Profil Peserta'!$C$11,'Bobot Kategori'!$B$6:$B$11,0),MATCH(C45,'Bobot Kategori'!$C$5:$E$5,0))) -> 0.03 | M45: =L45*J45 -> 0.15
B46: 40 | C46: Governance | D46: Integritas & Kepatuhan | E46: 7.2 | F46: Saluran pelaporan pelanggaran (whistleblowing) independen | G46: SOP whistleblowing, bukti pengelolaan independen | H46: IUP,IUJP-KONSULTASI,IUJP-OPERASIONAL,IUJP-DRILLING,IUJP-PENGOLAHAN,IUJP-PENUNJANG | I46: 0.03 | J46: 5 | K46: =IF(ISNUMBER(SEARCH(","&'Profil Peserta'!$C$11&",", ","&H46&",")),1,0) -> 1 | L46: =IF(K46=0,0,(I46/SUMIFS($I$7:$I$55,$C$7:$C$55,C46,$K$7:$K$55,1))*INDEX('Bobot Kategori'!$C$6:$E$11,MATCH('Profil Peserta'!$C$11,'Bobot Kategori'!$B$6:$B$11,0),MATCH(C46,'Bobot Kategori'!$C$5:$E$5,0))) -> 0.03 | M46: =L46*J46 -> 0.15
B47: 41 | C47: Governance | D47: Integritas & Kepatuhan | E47: 7.3 | F47: Sertifikasi ISO 37301 (Sistem Manajemen Kepatuhan) | G47: Sertifikat ISO 37301 | H47: IUP,IUJP-KONSULTASI,IUJP-OPERASIONAL,IUJP-DRILLING,IUJP-PENGOLAHAN,IUJP-PENUNJANG | I47: 0.02 | J47: 5 | K47: =IF(ISNUMBER(SEARCH(","&'Profil Peserta'!$C$11&",", ","&H47&",")),1,0) -> 1 | L47: =IF(K47=0,0,(I47/SUMIFS($I$7:$I$55,$C$7:$C$55,C47,$K$7:$K$55,1))*INDEX('Bobot Kategori'!$C$6:$E$11,MATCH('Profil Peserta'!$C$11,'Bobot Kategori'!$B$6:$B$11,0),MATCH(C47,'Bobot Kategori'!$C$5:$E$5,0))) -> 0.02 | M47: =L47*J47 -> 0.1
B48: 42 | C48: Governance | D48: Integritas & Kepatuhan | E48: 7.4a | F48: Transparansi pembayaran kepada pemerintah (EITI/Publish What You Pay) | G48: Laporan EITI, data royalti & pajak SDA | H48: IUP | I48: 0.03 | J48: 5 | K48: =IF(ISNUMBER(SEARCH(","&'Profil Peserta'!$C$11&",", ","&H48&",")),1,0) -> 1 | L48: =IF(K48=0,0,(I48/SUMIFS($I$7:$I$55,$C$7:$C$55,C48,$K$7:$K$55,1))*INDEX('Bobot Kategori'!$C$6:$E$11,MATCH('Profil Peserta'!$C$11,'Bobot Kategori'!$B$6:$B$11,0),MATCH(C48,'Bobot Kategori'!$C$5:$E$5,0))) -> 0.03 | M48: =L48*J48 -> 0.15
...

Sheet ESG Score Summary
B2: ESG Score Summary
B3: ="Profil Peserta Aktif: " & 'Profil Peserta'!$C$11 -> Profil Peserta Aktif: IUP
B5: Pilar | C5: Bobot Target | D5: Total Bobot Ternormalisasi (cek) | E5: Total Skor Terbobot (mentah) | F5: Skor Rata-rata Mentah (0-5) | G5: Batas Maks. (Red Flag) | H5: Skor Rata-rata Final (0-5) | I5: Skor Terbobot Final | J5: Level Kematangan
B6: Environmental | C6: =INDEX('Bobot Kategori'!$C$6:$E$11,MATCH('Profil Peserta'!$C$11,'Bobot Kategori'!$B$6:$B$11,0),MATCH(B6,'Bobot Kategori'!$C$5:$E$5,0)) -> 0.35 | D6: =SUMIFS('Master Checklist'!$L$7:$L$55,'Master Checklist'!$C$7:$C$55,B6) -> 0.35 | E6: =SUMIFS('Master Checklist'!$M$7:$M$55,'Master Checklist'!$C$7:$C$55,B6) -> 1.75 | F6: =IF(D6=0,0,E6/D6) -> 5 | G6: =IF('Red Flag'!$D$8="Ya",2,5) -> 2 | H6: =MIN(F6,G6) -> 2 | I6: =H6*D6 -> 0.7 | J6: =IF(H6>=4,"Leadership",IF(H6>=3,"Integration",IF(H6>=2,"Foundation","Belum Memenuhi"))) -> Foundation
B7: Social | C7: =INDEX('Bobot Kategori'!$C$6:$E$11,MATCH('Profil Peserta'!$C$11,'Bobot Kategori'!$B$6:$B$11,0),MATCH(B7,'Bobot Kategori'!$C$5:$E$5,0)) -> 0.4 | D7: =SUMIFS('Master Checklist'!$L$7:$L$55,'Master Checklist'!$C$7:$C$55,B7) -> 0.4 | E7: =SUMIFS('Master Checklist'!$M$7:$M$55,'Master Checklist'!$C$7:$C$55,B7) -> 2 | F7: =IF(D7=0,0,E7/D7) -> 5 | G7: =IF('Red Flag'!$D$7="Ya",2,5) -> 5 | H7: =MIN(F7,G7) -> 5 | I7: =H7*D7 -> 2 | J7: =IF(H7>=4,"Leadership",IF(H7>=3,"Integration",IF(H7>=2,"Foundation","Belum Memenuhi"))) -> Leadership
B8: Governance | C8: =INDEX('Bobot Kategori'!$C$6:$E$11,MATCH('Profil Peserta'!$C$11,'Bobot Kategori'!$B$6:$B$11,0),MATCH(B8,'Bobot Kategori'!$C$5:$E$5,0)) -> 0.25 | D8: =SUMIFS('Master Checklist'!$L$7:$L$55,'Master Checklist'!$C$7:$C$55,B8) -> 0.25 | E8: =SUMIFS('Master Checklist'!$M$7:$M$55,'Master Checklist'!$C$7:$C$55,B8) -> 1.25 | F8: =IF(D8=0,0,E8/D8) -> 5 | G8: =IF('Red Flag'!$D$9="Ya",2,5) -> 2 | H8: =MIN(F8,G8) -> 2 | I8: =H8*D8 -> 0.5 | J8: =IF(H8>=4,"Leadership",IF(H8>=3,"Integration",IF(H8>=2,"Foundation","Belum Memenuhi"))) -> Foundation
B10: Catatan: 'Skor Rata-rata Final' = MIN(Skor Mentah, Batas Maksimal Red Flag). Batas Maksimal ditarik otomatis dari sheet 'Red Flag' bagian A. Jika tidak ada Red Flag aktif, batas maksimal = 5 (tidak membatasi apa pun). 'Skor Terbobot Final' dipakai sebagai basis Grand Score di sheet 'Award Level'.

Sheet Award Level
B2: Award Level & Grand Score
B3: ="Profil Peserta Aktif: " & 'Profil Peserta'!$C$11 -> Profil Peserta Aktif: IUP
B5: Komponen | C5: Nilai
B6: Skor Environmental (0-5, final) | C6: ='ESG Score Summary'!H6 -> 2
B7: Skor Social (0-5, final) | C7: ='ESG Score Summary'!H7 -> 5
B8: Skor Governance (0-5, final) | C8: ='ESG Score Summary'!H8 -> 2
B10: Grand Score (skala 0-100) | C10: =(SUM('ESG Score Summary'!I6:I8)/5)*100 -> 64
B11: Skor Minimum per Pilar (syarat Award) | C11: =MIN(C6:C8) -> 2
B13: Kategori Award | C13: =IF('Red Flag'!$D$17="Ya","DISKUALIFIKASI TOTAL (Red Flag B)",IF(C11>=4,"ESG LEADERSHIP AWARD",IF(C11>=3,"ESG INTEGRATION AWARD",IF(C11>=2,"ESG FOUNDATION RECOGNITION","BELUM MEMENUHI SYARAT AWARD")))) -> ESG FOUNDATION RECOGNITION
B15: THE GRAND ESG MINING CHAMPION
B16: Syarat: Grand Score ≥ 85 DAN skor minimum tiap pilar ≥ 3,0 DAN tidak ada Red Flag aktif
B17: Eligibilitas Grand Award | C17: =IF('Red Flag'!$D$17="Ya","TIDAK ELIGIBLE (Diskualifikasi Total)",IF(OR('Red Flag'!$D$7="Ya",'Red Flag'!$D$8="Ya",'Red Flag'!$D$9="Ya"),"TIDAK ELIGIBLE (Red Flag Aktif)",IF(AND(C10>=85,C11>=3),"ELIGIBLE","TIDAK ELIGIBLE (Syarat Skor Belum Terpenuhi)"))) -> TIDAK ELIGIBLE (Red Flag Aktif)
B18: Status | C18: =IF(C17="ELIGIBLE","🏆 KANDIDAT THE GRAND ESG MINING CHAMPION","—") -> —
B20: Logika Kategori Award: ditentukan oleh PILAR TERLEMAH (bukan rata-rata), agar peserta tidak bisa menutupi kelemahan satu pilar dengan keunggulan pilar lain. Grand Award adalah predikat TERTINGGI, diberikan kepada peserta dengan Grand Score tertinggi DI ANTARA seluruh peserta yang berstatus 'ELIGIBLE' pada cycle Award yang sama — sheet ini menghitung eligibilitas per-peserta; penentuan pemenang akhir dilakukan dengan membandingkan status ELIGIBLE dan Grand Score antar seluruh workbook peserta. Status Red Flag ditarik otomatis dari sheet 'Red Flag'.

Sheet Red Flag
B2: Red Flag Policy
B3: Berlaku sama untuk peserta IUP maupun seluruh sub-jenis IUJP. Assessor wajib memverifikasi kondisi di bawah ini secara independen (bukan berdasarkan self-declare peserta) sebelum finalisasi skor.
B5: A. Pembatasan Skor Otomatis (Score Cap)
B6: No | C6: Kondisi | D6: Status Asesor | E6: Konsekuensi Otomatis
B7: 1 | C7: Insiden fatalitas pekerja (kematian akibat kecelakaan kerja) dalam 12 bulan terakhir | D7: Tidak | E7: Skor pilar Social dibatasi maksimal 2,0 dan peserta TIDAK ELIGIBLE untuk Grand Award
B8: 2 | C8: Kegagalan bendungan tailing (tailing dam failure) atau kebocoran bahan berbahaya (B3) ke lingkungan dalam 12 bulan terakhir | D8: Ya | E8: Skor pilar Environmental dibatasi maksimal 2,0 dan peserta TIDAK ELIGIBLE untuk Grand Award
B9: 3 | C9: Sanksi regulator berat: proses hukum berjalan atau sanksi pencabutan izin/teguran keras oleh pemerintah terkait pelanggaran lingkungan atau HAM yang BELUM diselesaikan | D9: Ya | E9: Skor pilar Governance dibatasi maksimal 2,0 dan peserta TIDAK ELIGIBLE untuk Grand Award
B11: B. Diskualifikasi Total (Seluruh Kategori Award, termasuk Grand Award)
B12: No | C12: Kondisi | D12: Status Asesor | E12: Konsekuensi
B13: 1 | C13: Temuan pelanggaran HAM berat (kerja paksa dan/atau pekerja anak) yang terverifikasi oleh otoritas atau audit independen | E13: Diskualifikasi total
B14: 2 | C14: Kasus korupsi/suap yang telah berkekuatan hukum tetap melibatkan manajemen perusahaan | E14: Diskualifikasi total
B15: 3 | C15: Data material dimanipulasi atau dipalsukan pada dokumen bukti yang diserahkan ke assessor | E15: Diskualifikasi total
B17: Apakah salah satu kondisi di atas (B) terpenuhi? | D17: Tidak
B19: Kolom 'Status Asesor' pada bagian A secara otomatis membatasi skor pilar terkait di sheet 'ESG Score Summary' dan menonaktifkan eligibilitas Grand Award di sheet 'Award Level'. Kolom pada bagian B (jika 'Ya') otomatis mendiskualifikasi peserta dari SELURUH kategori Award di sheet 'Award Level', terlepas dari skor yang dicapai.
